<?xml version="1.0"?>
<robot xmlns:xacro="http://www.ros.org/wiki/xacro"> 
	<xacro:macro name="link_2" params="*origin parent suffix color"> 
		<link name="${suffix}link_2">
			<xacro:default_inertial/>
			<visual>
				<geometry>
					<mesh scale="0.001 0.001 0.001" filename="package://clopema_description/meshes/link2.stl"/>
				</geometry>
				<material name="${color}" />
				<origin xyz="0 0 0"/>
			</visual>
			<collision>
				<geometry>
					<box size="0.47 0.400 0.4000"/>
				</geometry>
				<origin xyz="0.015 0.0 ${0.20+0.1785}"/>
			</collision>
		</link>
		<joint name="${suffix}joint_s" type="revolute">
			<axis xyz="0 0 1" />
			<limit lower="-${170*TO_RAD}" upper="${170*TO_RAD}" velocity="${220*TO_RAD}" effort="1000.0" />
			<child link="${suffix}link_2"/>
			<insert_block name="origin" /> 
			<parent link="${suffix}${parent}"/>
		</joint>
	</xacro:macro>
</robot>
