<?xml version="1.0"?>
<robot name="ptu_d46"
       xmlns:xacro="http://ros.org/wiki/xacro">
  <xacro:property name="pan_velocity" value="1.0" />
  <xacro:property name="pan_range" value="2.775" />
  <xacro:property name="tilt_velocity" value="1.0" />
  <xacro:property name="tilt_up_range" value="0.52" />
  <xacro:property name="tilt_down_range" value="0.82" />
  <xacro:property name="joint_effort" value="30" />
    
  <xacro:macro name="d46_stepper_module"
               params="ptu_name joint_name">
    <link name="${ptu_name}_${joint_name}">
      <!-- <inertial>
        <mass value="0.65" />
        <inertia ... ? />
      </inertial> -->
      <visual>
        <material name="ptu_body_color">
          <color rgba="0.3 0.3 0.3 1.0" />
        </material>
        <geometry>
          <box size="0.045 0.065 0.044" />
        </geometry>
        <origin xyz="0 0.011 0" />
      </visual>
      <visual>
        <geometry>
          <box size="0.046 0.044 0.044" />
        </geometry>
        <origin xyz="-0.045 0.0215 0" />
      </visual>
      <visual>
        <geometry>
          <cylinder length="0.015" radius="0.005" />
        </geometry>
        <origin xyz="-0.074 0.021 0" rpy="0 1.57 0" />
      </visual>
    </link>
  </xacro:macro>

  <xacro:macro name="ptu_d46" params="name">
    <d46_stepper_module ptu_name="${name}" joint_name="pan_ptu" /> <!-- Edit -->
    <d46_stepper_module ptu_name="${name}" joint_name="tilt_ptu" /> <!-- Edit -->
    <link name="${name}_base_ptu" /> <!-- Edit -->
    <link name="${name}_tilted_ptu" /> <!-- Edit -->
    <link name="${name}_mount_ptu" /> <!-- Edit -->

    <!-- There's an offset between the origin of the pan joint and the origin of 
         the overall device, which is between the mounting screws on its base. -->
    <joint name="${name}_base_ptu" type="fixed"> <!-- Edit -->
      <parent link="${name}_base_ptu"/> <!-- Edit -->
      <child link="${name}_pan_ptu"/> <!-- Edit -->
      <origin xyz="0 -0.009525 0.02286"/>
    </joint>

    <!-- The pan joint -->
    <joint name="${name}_to_pan" type="revolute"> <!-- Edit -->
      <parent link="${name}_pan_ptu" /> <!-- Edit -->
      <origin xyz="0 0 0.068834" rpy="-1.5708 0 0" />
      <child link="${name}_tilt_ptu" /> <!-- Edit -->
      <axis xyz="0 -1 0" rpy="0 0 0" />
      <limit lower="-${pan_range}" upper="${pan_range}"
             effort="${joint_effort}" velocity="${pan_velocity}" />
    </joint>

    <!-- The tilt joint -->
    <joint name="${name}_to_tilt" type="revolute"> <!-- Edit -->
      <parent link="${name}_tilt_ptu" /> <!-- Edit -->
      <origin xyz="0 0 0" rpy="-1.5708 0 0" />
      <child link="${name}_tilted_ptu" /> <!-- Edit -->
      <axis xyz="0 1 0" />
      <limit lower="${-tilt_down_range}" upper="${tilt_up_range}"
             effort="${joint_effort}" velocity="${tilt_velocity}" />
    </joint>

    <!-- Fixed joint to provide a convenient attachment point for accessories. -->
    <joint name="${name}_mount_ptu" type="fixed"> <!-- Edit -->
      <parent link="${name}_tilted_ptu"/> <!-- Edit -->
      <child link="${name}_mount_ptu"/> <!-- Edit -->
      <origin xyz="0 0 -0.039116" rpy="3.1416 0 0" />
    </joint>
  </xacro:macro>
</robot>
